<?xml version="1.0"?>
<robot name="my_bot">

  <material name="black">
    <color rgba="0 0 0 1"/>
  </material>
  <material name="white">
    <color rgba="1 1 1 1"/>
  </material>

  <link name="base_link">
    <visual>
      <geometry>
        <box size="0.6 0.5 0.1"/>
      </geometry>
      <material name="white"/>
    </visual>
    <collision>
      <geometry>
        <box size="0.6 0.5 0.1"/>
      </geometry>
    </collision>
    <inertial>
      <mass value="10"/>
      <inertia ixx="0.6" ixy="0.0" ixz="0.0" iyy="0.4" iyz="0.0" izz="0.2"/>
    </inertial>
  </link>

  <link name="right_front_wheel">
    <visual>
      <geometry>
        <cylinder length="0.1" radius="0.125"/>
      </geometry>
      <material name="black"/>
      <origin rpy="1.570796 0 0" xyz="0 0 0"/>
    </visual>
    <collision>
      <geometry>
        <cylinder length="0.1" radius="0.125"/>
      </geometry>
    </collision>
    <inertial>
      <mass value="1"/>
      <inertia ixx="0.2" ixy="0.0" ixz="0.0" iyy="0.2" iyz="0.0" izz="0.1"/>
    </inertial>
  </link>

  <joint name="right_front_wheel_joint" type="continuous">
    <parent link="base_link"/>
    <child link="right_front_wheel"/>
    <origin rpy="0 0 0" xyz="0.2 0.2 -0.175"/>
  </joint>

  <link name="right_back_wheel">
    <visual>
      <geometry>
        <cylinder length="0.1" radius="0.125"/>
      </geometry>
      <material name="black"/>
      <origin rpy="1.570796 0 0" xyz="0 0 0"/>
    </visual>
    <collision>
      <geometry>
        <cylinder length="0.1" radius="0.125"/>
      </geometry>
    </collision>
    <inertial>
      <mass value="1"/>
      <inertia ixx="0.2" ixy="0.0" ixz="0.0" iyy="0.2" iyz="0.0" izz="0.1"/>
    </inertial>
  </link>

  <joint name="right_back_wheel_joint" type="continuous">
    <parent link="base_link"/>
    <child link="right_back_wheel"/>
    <origin rpy="0 0 0" xyz="-0.2 0.2 -0.175"/>
  </joint>

  <link name="left_front_wheel">
    <visual>
      <geometry>
        <cylinder length="0.1" radius="0.125"/>
      </geometry>
      <material name="black"/>
      <origin rpy="1.570796 0 0" xyz="0 0 0"/>
    </visual>
    <collision>
      <geometry>
        <cylinder length="0.1" radius="0.125"/>
      </geometry>
    </collision>
    <inertial>
      <mass value="1"/>
      <inertia ixx="0.2" ixy="0.0" ixz="0.0" iyy="0.2" iyz="0.0" izz="0.1"/>
    </inertial>
  </link>

  <joint name="left_front_wheel_joint" type="continuous">
    <parent link="base_link"/>
    <child link="left_front_wheel"/>
    <origin rpy="0 0 0" xyz="0.2 -0.2 -0.175"/>
  </joint>

  <link name="left_back_wheel">
    <visual>
      <geometry>
        <cylinder length="0.1" radius="0.125"/>
      </geometry>
      <material name="black"/>
      <origin rpy="1.570796 0 0" xyz="0 0 0"/>
    </visual>
    <collision>
      <geometry>
        <cylinder length="0.1" radius="0.125"/>
      </geometry>
    </collision>
    <inertial>
      <mass value="1"/>
      <inertia ixx="0.2" ixy="0.0" ixz="0.0" iyy="0.2" iyz="0.0" izz="0.1"/>
    </inertial>
  </link>

  <joint name="left_back_wheel_joint" type="continuous">
    <parent link="base_link"/>
    <child link="left_back_wheel"/>
    <origin rpy="0 0 0" xyz="-0.2 -0.2 -0.175"/>
  </joint>
  
  <link name="hokuyo_link">
    <visual>
      <geometry>
        <box size="0.1 0.1 0.01"/>
      </geometry>
      <material name="black"/>
      <origin rpy="0 0 0" xyz="0 0 0"/>
    </visual>
    <collision>
      <geometry>
        <box size="0.1 0.1 0.01"/>
      </geometry>
    </collision>
    <inertial>
      <mass value="0.1"/>
      <inertia ixx="0.05" ixy="0.0" ixz="0.05" iyy="0.1" iyz="0.0" izz="0.01"/>
    </inertial>
  </link>

  <joint name="hokuyo_joint" type="fixed">
    <parent link="base_link"/>
    <child link="hokuyo_link"/>
    <origin rpy="0 0 0" xyz="0.35 0 -0.04"/>
  </joint>

  <link name="kinect_base">
    <visual>
      <geometry>
        <box size="0.05 0.1 0.1"/>
      </geometry>
      <material name="black"/>
      <origin rpy="0 0 0" xyz="0 0 0"/>
    </visual>
    <collision>
      <geometry>
        <box size="0.05 0.1 0.1"/>
      </geometry>
    </collision>
    <inertial>
      <mass value="0.5"/>
      <inertia ixx="0.01" ixy="0.0" ixz="0.1" iyy="0.1" iyz="0.0" izz="0.1"/>
    </inertial>
  </link>

  <joint name="kinect_base_joint" type="fixed">
    <parent link="base_link"/>
    <child link="kinect_base"/>
    <origin rpy="0 0 0" xyz="0.275 0 0.1"/>
  </joint>

  <link name="kinect_link">
    <visual>
      <geometry>
        <box size="0.1 0.1 0.01"/>
      </geometry>
      <material name="white"/>
      <origin rpy="0 0 0" xyz="0 0 0"/>
    </visual>
    <collision>
      <geometry>
        <box size="0.1 0.1 0.01"/>
      </geometry>
    </collision>
    <inertial>
      <mass value="0.1"/>
      <inertia ixx="0.05" ixy="0.0" ixz="0.05" iyy="0.1" iyz="0.0" izz="0.01"/>
    </inertial>
  </link>

  <joint name="kinect_joint" type="fixed">
    <parent link="kinect_base"/>
    <child link="kinect_link"/>
    <origin rpy="0 0 0" xyz="0.075 0 0.045"/>
  </joint>
  
</robot>
